Workbook
Name CPI_2012: #REF!
Name CPI_2012: #REF!

Sheet CPI2025
A1: Corruption Perceptions Index 2025: Global scores
A2: EMBARGOED UNTIL 10.02.2026
A4: Country / Territory | B4: ISO3 | C4: Region | D4: CPI 2025 score | E4: Rank | F4: Standard error 2025 | G4: Number of sources | H4: Lower CI | I4: Upper CI | J4: African Development Bank CPIA | K4: Bertelsmann Foundation Sustainable Governance Index | L4: Bertelsmann Foundation Transformation Index | M4: Economist Intelligence Unit Country Ratings | N4: Freedom House Nations In Transit | O4: Global Insights Country Risk Ratings | P4: IMD World Competitiveness Yearbook | Q4: PERC Asia Risk Guide | R4: PRS International Country Risk Guide | S4: Varieties of Democracy Project | T4: World Bank CPIA | U4: World Economic Forum EOS | V4: World Justice Project Rule of Law Index
A5: Denmark | B5: DNK | C5: =VLOOKUP(B5,'CPI Timeseries 2012 - 2025'!B:C,2,0) -> WE/EU | D5: 89 | E5: 1 | F5: 1.882284 | G5: 8 | H5: 85.91306 | I5: 92.08694 | K5: 97.34405 | M5: 82.83861 | O5: 85.22919 | P5: 93.08286 | R5: 100 | S5: 75.12891 | U5: 93.58622 | V5: 87.02797
A6: Finland | B6: FIN | C6: =VLOOKUP(B6,'CPI Timeseries 2012 - 2025'!B:C,2,0) -> WE/EU | D6: 88 | E6: 2 | F6: 1.806286 | G6: 8 | H6: 85.03769 | I6: 90.96231 | K6: 97.34405 | M6: 82.83861 | O6: 85.22919 | P6: 93.08286 | R6: 96.30098 | S6: 73.75974 | U6: 90.56377 | V6: 84.42215
A7: Singapore | B7: SGP | C7: =VLOOKUP(B7,'CPI Timeseries 2012 - 2025'!B:C,2,0) -> AP | D7: 84 | E7: 3 | F7: 1.518263 | G7: 9 | H7: 81.51005 | I7: 86.48995 | L7: 77.22701 | M7: 82.83861 | O7: 85.22919 | P7: 90.84637 | Q7: 88.35136 | R7: 78.1461 | S7: 73.07516 | U7: 99.16616 | V7: 85.29076
A8: New Zealand | B8: NZL | C8: =VLOOKUP(B8,'CPI Timeseries 2012 - 2025'!B:C,2,0) -> AP | D8: 81 | E8: 4 | F8: 2.036385 | G8: 8 | H8: 77.66033 | I8: 84.33967 | K8: 87.17163 | M8: 82.83861 | O8: 85.22919 | P8: 72.44612 | R8: 96.30098 | S8: 74.44433 | U8: 68.94151 | V8: 82.68494
A9: Norway | B9: NOR | C9: =VLOOKUP(B9,'CPI Timeseries 2012 - 2025'!B:C,2,0) -> WE/EU | D9: 81 | E9: 4 | F9: 1.618172 | G9: 8 | H9: 78.3462 | I9: 83.6538 | K9: 87.17163 | M9: 82.83861 | O9: 85.22919 | P9: 78.64731 | R9: 87.22354 | S9: 74.44433 | U9: 67.08154 | V9: 84.42215
A10: Sweden | B10: SWE | C10: =VLOOKUP(B10,'CPI Timeseries 2012 - 2025'!B:C,2,0) -> WE/EU | D10: 80 | E10: 6 | F10: 2.525394 | G10: 8 | H10: 75.85835 | I10: 84.14165 | K10: 87.17163 | M10: 82.83861 | O10: 85.22919 | P10: 70.71792 | R10: 96.30098 | S10: 74.44433 | U10: 60.80412 | V10: 84.42215
A11: Switzerland | B11: CHE | C11: =VLOOKUP(B11,'CPI Timeseries 2012 - 2025'!B:C,2,0) -> WE/EU | D11: 80 | E11: 6 | F11: 2.194526 | G11: 7 | H11: 76.40098 | I11: 83.59902 | K11: 87.17163 | M11: 82.83861 | O11: 71.92592 | P11: 87.49162 | R11: 87.22354 | S11: 73.75974 | U11: 68.47652
A12: Luxembourg | B12: LUX | C12: =VLOOKUP(B12,'CPI Timeseries 2012 - 2025'!B:C,2,0) -> WE/EU | D12: 78 | E12: 8 | F12: 2.192617 | G12: 7 | H12: 74.40411 | I12: 81.59589 | M12: 66.72388 | O12: 71.92592 | P12: 78.64731 | R12: 87.22354 | S12: 73.07516 | U12: 89.40128 | V12: 78.3419
A13: Netherlands | B13: NLD | C13: =VLOOKUP(B13,'CPI Timeseries 2012 - 2025'!B:C,2,0) -> WE/EU | D13: 78 | E13: 8 | F13: 2.403906 | G13: 8 | H13: 74.05759 | I13: 81.94241 | K13: 56.65436 | M13: 82.83861 | O13: 71.92592 | P13: 88.81319 | R13: 87.22354 | S13: 73.75974 | U13: 84.05384 | V13: 80.07912
A14: Germany | B14: DEU | C14: =VLOOKUP(B14,'CPI Timeseries 2012 - 2025'!B:C,2,0) -> WE/EU | D14: 77 | E14: 10 | F14: 1.85484 | G14: 8 | H14: 73.95806 | I14: 80.04194 | K14: 76.99921 | M14: 82.83861 | O14: 71.92592 | P14: 88.81319 | R14: 78.1461 | S14: 73.75974 | U14: 61.26911 | V14: 79.21051
A15: Iceland | B15: ISL | C15: =VLOOKUP(B15,'CPI Timeseries 2012 - 2025'!B:C,2,0) -> WE/EU | D15: 77 | E15: 10 | F15: 3.963409 | G15: 5 | H15: 70.50001 | I15: 83.49999 | M15: 66.72388 | O15: 71.92592 | P15: 95.11604 | R15: 78.1461 | S15: 73.75974
A16: Australia | B16: AUS | C16: =VLOOKUP(B16,'CPI Timeseries 2012 - 2025'!B:C,2,0) -> AP | D16: 76 | E16: 12 | F16: 1.429308 | G16: 9 | H16: 73.65594 | I16: 78.34406 | K16: 66.82678 | M16: 66.72388 | O16: 85.22919 | P16: 73.97101 | Q16: 88.15337 | R16: 78.1461 | S16: 73.07516 | U16: 73.82396 | V16: 80.07912
A17: Estonia | B17: EST | C17: =VLOOKUP(B17,'CPI Timeseries 2012 - 2025'!B:C,2,0) -> WE/EU | D17: 76 | E17: 12 | F17: 1.070026 | G17: 10 | H17: 74.24516 | I17: 77.75484 | K17: 87.17163 | L17: 85.82413 | M17: 66.72388 | N17: 74.05621 | O17: 71.92592 | P17: 78.34233 | R17: 69.06866 | S17: 73.07516 | U17: 80.79888 | V17: 75.73608
A18: Hong Kong | B18: HKG | C18: =VLOOKUP(B18,'CPI Timeseries 2012 - 2025'!B:C,2,0) -> AP | D18: 76 | E18: 12 | F18: 2.420668 | G18: 8 | H18: 72.03011 | I18: 79.96989 | M18: 82.83861 | O18: 58.82121 | P18: 90.94803 | Q18: 78.94705 | R18: 69.06866 | S18: 69.65223 | U18: 86.8438 | V18: 73.13026
A19: Ireland | B19: IRL | C19: =VLOOKUP(B19,'CPI Timeseries 2012 - 2025'!B:C,2,0) -> WE/EU | D19: 76 | E19: 12 | F19: 1.277815 | G19: 8 | H19: 73.90438 | I19: 78.09562 | K19: 76.99921 | M19: 66.72388 | O19: 71.92592 | P19: 85.86509 | R19: 78.1461 | S19: 73.07516 | U19: 77.77641 | V19: 77.4733
A20: Canada | B20: CAN | C20: =VLOOKUP(B20,'CPI Timeseries 2012 - 2025'!B:C,2,0) -> AME | D20: 75 | E20: 16 | F20: 1.959374 | G20: 8 | H20: 71.78663 | I20: 78.21337 | K20: 87.17163 | M20: 82.83861 | O20: 71.92592 | P20: 74.17432 | R20: 78.1461 | S20: 73.07516 | U20: 58.24664 | V20: 76.60469
A21: Uruguay | B21: URY | C21: =VLOOKUP(B21,'CPI Timeseries 2012 - 2025'!B:C,2,0) -> AME | D21: 73 | E21: 17 | F21: 1.320409 | G21: 7 | H21: 70.83453 | I21: 75.16547 | L21: 81.52557 | M21: 66.72388 | O21: 71.92592 | R21: 78.1461 | S21: 71.70599 | U21: 73.59147 | V21: 70.52444
A22: Bhutan | B22: BTN | C22: =VLOOKUP(B22,'CPI Timeseries 2012 - 2025'!B:C,2,0) -> AP | D22: 71 | E22: 18 | F22: 2.063194 | G22: 4 | H22: 67.61636 | I22: 74.38364 | L22: 72.92845 | O22: 71.92592 | S22: 64.17554 | T22: 75.11877
A23: Japan | B23: JPN | C23: =VLOOKUP(B23,'CPI Timeseries 2012 - 2025'!B:C,2,0) -> AP | D23: 71 | E23: 18 | F23: 2.489124 | G23: 9 | H23: 66.91784 | I23: 75.08216 | K23: 46.48194 | M23: 66.72388 | O23: 71.92592 | P23: 67.87148 | Q23: 79.73899 | R23: 59.99121 | S23: 71.0214 | U23: 92.42374 | V23: 78.3419
A24: United Kingdom | B24: GBR | C24: =VLOOKUP(B24,'CPI Timeseries 2012 - 2025'!B:C,2,0) -> WE/EU | D24: 70 | E24: 20 | F24: 1.576231 | G24: 8 | H24: 67.41498 | I24: 72.58502 | K24: 76.99921 | M24: 66.72388 | O24: 71.92592 | P24: 57.70559 | R24: 69.06866 | S24: 72.39057 | U24: 66.61655 | V24: 80.07912
A25: Austria | B25: AUT | C25: =VLOOKUP(B25,'CPI Timeseries 2012 - 2025'!B:C,2,0) -> WE/EU | D25: 69 | E25: 21 | F25: 1.246618 | G25: 8 | H25: 66.95554 | I25: 71.04446 | K25: 66.82678 | M25: 66.72388 | O25: 58.82121 | P25: 76.61414 | R25: 69.06866 | S25: 67.59846 | U25: 70.104 | V25: 74.86747
A26: Belgium | B26: BEL | C26: =VLOOKUP(B26,'CPI Timeseries 2012 - 2025'!B:C,2,0) -> WE/EU | D26: 69 | E26: 21 | F26: 1.414537 | G26: 8 | H26: 66.68016 | I26: 71.31984 | K26: 66.82678 | M26: 66.72388 | O26: 71.92592 | P26: 76.91911 | R26: 69.06866 | S26: 73.07516 | U26: 56.85166 | V26: 73.99887
A27: United Arab Emirates | B27: ARE | C27: =VLOOKUP(B27,'CPI Timeseries 2012 - 2025'!B:C,2,0) -> MENA | D27: 69 | E27: 21 | F27: 2.245328 | G27: 8 | H27: 65.31767 | I27: 72.68233 | L27: 60.03276 | M27: 66.72388 | O27: 58.82121 | P27: 86.98334 | R27: 59.99121 | S27: 67.59846 | U27: 77.77641 | V27: 71.39305
A28: Barbados | B28: BRB | C28: =VLOOKUP(B28,'CPI Timeseries 2012 - 2025'!B:C,2,0) -> AME | D28: 68 | E28: 24 | F28: 3.120304 | G28: 3 | H28: 62.8827 | I28: 73.1173 | O28: 71.92592 | S28: 70.33681 | V28: 60.96977
A29: Seychelles | B29: SYC | C29: =VLOOKUP(B29,'CPI Timeseries 2012 - 2025'!B:C,2,0) -> SSA | D29: 68 | E29: 24 | F29: 2.354847 | G29: 4 | H29: 64.13805 | I29: 71.86195 | J29: 60.36055 | M29: 66.72388 | O29: 71.92592 | S29: 71.70599
A30: Taiwan | B30: TWN | C30: =VLOOKUP(B30,'CPI Timeseries 2012 - 2025'!B:C,2,0) -> AP | D30: 68 | E30: 24 | F30: 1.70772 | G30: 8 | H30: 65.19934 | I30: 70.80066 | L30: 81.52557 | M30: 66.72388 | O30: 71.92592 | P30: 68.78641 | Q30: 62.61324 | R30: 59.99121 | S30: 59.38344 | U30: 72.89397
A31: France | B31: FRA | C31: =VLOOKUP(B31,'CPI Timeseries 2012 - 2025'!B:C,2,0) -> WE/EU | D31: 66 | E31: 27 | F31: 1.83174 | G31: 8 | H31: 62.99595 | I31: 69.00405 | K31: 66.82678 | M31: 66.72388 | O31: 58.82121 | P31: 55.4691 | R31: 78.1461 | S31: 71.70599 | U31: 56.61917 | V31: 70.52444
A32: Lithuania | B32: LTU | C32: =VLOOKUP(B32,'CPI Timeseries 2012 - 2025'!B:C,2,0) -> WE/EU | D32: 65 | E32: 28 | F32: 1.608554 | G32: 10 | H32: 62.36197 | I32: 67.63803 | K32: 66.82678 | L32: 72.92845 | M32: 50.60913 | N32: 66.61157 | O32: 58.82121 | P32: 68.88806 | R32: 50.91377 | S32: 63.49095 | U32: 84.51883 | V32: 69.65583
A33: Bahamas | B33: BHS | C33: =VLOOKUP(B33,'CPI Timeseries 2012 - 2025'!B:C,2,0) -> AME | D33: 64 | E33: 29 | F33: 6.560889 | G33: 3 | H33: 53.24014 | I33: 74.75986 | O33: 58.82121 | R33: 78.1461 | V33: 54.88952
A34: United States of America | B34: USA | C34: =VLOOKUP(B34,'CPI Timeseries 2012 - 2025'!B:C,2,0) -> AME | D34: 64 | E34: 29 | F34: 2.638514 | G34: 9 | H34: 59.67284 | I34: 68.32716 | K34: 66.82678 | M34: 66.72388 | O34: 85.22919 | P34: 50.69114 | Q34: 36.77613 | R34: 69.06866 | S34: 71.70599 | U34: 62.1991 | V34: 69.65583
A35: Brunei Darussalam | B35: BRN | C35: =VLOOKUP(B35,'CPI Timeseries 2012 - 2025'!B:C,2,0) -> AP | D35: 63 | E35: 31 | F35: 5.629506 | G35: 3 | H35: 53.76761 | I35: 72.23239 | O35: 71.92592 | R35: 50.91377 | U35: 64.75657
A36: Chile | B36: CHL | C36: =VLOOKUP(B36,'CPI Timeseries 2012 - 2025'!B:C,2,0) -> AME | D36: 63 | E36: 31 | F36: 2.333968 | G36: 8 | H36: 59.17229 | I36: 66.82771 | L36: 81.52557 | M36: 66.72388 | O36: 58.82121 | P36: 48.45464 | R36: 59.99121 | S36: 69.65223 | U36: 53.3642 | V36: 63.57559
A37: Korea, South | B37: KOR | C37: =VLOOKUP(B37,'CPI Timeseries 2012 - 2025'!B:C,2,0) -> AP | D37: 63 | E37: 31 | F37: 1.515392 | G37: 9 | H37: 60.51476 | I37: 65.48524 | L37: 60.03276 | M37: 66.72388 | O37: 58.82121 | P37: 48.96294 | Q37: 57.26764 | R37: 75.96751 | S37: 64.17554 | U37: 62.4316 | V37: 70.52444
A38: Saint Vincent and the Grenadines | B38: VCT | C38: =VLOOKUP(B38,'CPI Timeseries 2012 - 2025'!B:C,2,0) -> AME | D38: 63 | E38: 31 | F38: 1.949243 | G38: 3 | H38: 59.80324 | I38: 66.19675 | O38: 58.82121 | T38: 63.1382 | V38: 66.18141
A39: Cabo Verde | B39: CPV | C39: =VLOOKUP(B39,'CPI Timeseries 2012 - 2025'!B:C,2,0) -> SSA | D39: 62 | E39: 35 | F39: 4.233232 | G39: 5 | H39: 55.0575 | I39: 68.9425 | J39: 55.34176 | O39: 71.92592 | S39: 57.32968 | T39: 75.11877 | U39: 47.78427
A40: Israel | B40: ISR | C40: =VLOOKUP(B40,'CPI Timeseries 2012 - 2025'!B:C,2,0) -> MENA | D40: 62 | E40: 35 | F40: 2.599745 | G40: 5 | H40: 57.73642 | I40: 66.26358 | K40: 66.82678 | M40: 66.72388 | O40: 58.82121 | R40: 50.91377 | S40: 66.91388
A41: Dominica | B41: DMA | C41: =VLOOKUP(B41,'CPI Timeseries 2012 - 2025'!B:C,2,0) -> AME | D41: 60 | E41: 37 | F41: 1.746044 | G41: 3 | H41: 57.13649 | I41: 62.86351 | O41: 58.82121 | T41: 63.1382 | V41: 56.62674
...

Sheet CPI Timeseries 2012 - 2025
A1: Corruption Perceptions Index 2025: Score timeseries since 2012
A2: EMBARGOED UNTIL 10.02.2026
A4: Country / Territory | B4: ISO3 | C4: Region | D4: CPI score 2025 | E4: Rank 2025 | F4: Sources 2025 | G4: Standard error 2025 | H4: CPI score 2024 | I4: Rank 2024 | J4: Sources 2024 | K4: Standard error 2024 | L4: CPI score 2023 | M4: Rank 2023 | N4: Sources 2023 | O4: Standard error 2023 | P4: CPI score 2022 | Q4: Rank 2022 | R4: Sources 2022 | S4: Standard error 2022 | T4: CPI score 2021 | U4: Rank 2021 | V4: Sources 2021 | W4: Standard error 2021 | X4: CPI score 2020 | Y4: Rank 2020 | Z4: Sources 2020 | AA4: Standard error 2020 | AB4: CPI score 2019 | AC4: Rank 2019 | AD4: Sources 2019 | AE4: Standard error 2019 | AF4: CPI score 2018 | AG4: Rank 2018 | AH4: Sources 2018 | AI4: Standard error 2018 | AJ4: CPI score 2017 | AK4: Rank 2017 | AL4: Sources 2017 | AM4: Standard error 2017 | AN4: CPI score 2016 | AO4: Sources 2016 | AP4: Standard error 2016 | AQ4: CPI score 2015 | AR4: Sources 2015 | AS4: Standard error 2015 | AT4: CPI score 2014 | AU4: Sources 2014 | AV4: Standard error 2014 | AW4: CPI Score 2013 | AX4: Sources 2013 | AY4: Standard error 2013 | AZ4: CPI Score 2012 | BA4: Sources 2012 | BB4: Standard error 2012
A5: Afghanistan | B5: AFG | C5: AP | D5: 16 | E5: 169 | F5: 5 | G5: 4.225913 | H5: 17 | I5: 165 | J5: 5 | K5: 5.759683 | L5: 20 | M5: 162 | N5: 5 | O5: 6.244771 | P5: 24 | Q5: 150 | R5: 4 | S5: 6.299999 | T5: 16 | U5: 174 | V5: 5 | W5: 2.12416 | X5: 19 | Y5: 165 | Z5: 5 | AA5: 2.440014 | AB5: 16 | AC5: 173 | AD5: 5 | AE5: 2.554536 | AF5: 16 | AG5: 172 | AH5: 5 | AI5: 1.41 | AJ5: 15 | AK5: 177 | AL5: 5 | AM5: 1.39 | AN5: 15 | AO5: 5 | AP5: 1.74 | AQ5: 11 | AR5: 4 | AS5: 3.49 | AT5: 12 | AU5: 4 | AV5: 1.29 | AW5: 8 | AX5: 3 | AY5: 3.3 | AZ5: 8 | BA5: 3 | BB5: 3.3
A6: Albania | B6: ALB | C6: ECA | D6: 39 | E6: 91 | F6: 7 | G6: 2.411099 | H6: 42 | I6: 80 | J6: 8 | K6: 3.030323 | L6: 37 | M6: 98 | N6: 7 | O6: 1.560074 | P6: 36 | Q6: 101 | R6: 8 | S6: 1.316355 | T6: 35 | U6: 110 | V6: 8 | W6: 1.326029 | X6: 36 | Y6: 104 | Z6: 8 | AA6: 0.915488 | AB6: 35 | AC6: 106 | AD6: 8 | AE6: 2.507669 | AF6: 36 | AG6: 99 | AH6: 8 | AI6: 1.65 | AJ6: 38 | AK6: 91 | AL6: 8 | AM6: 1.81 | AN6: 39 | AO6: 7 | AP6: 1.99 | AQ6: 36 | AR6: 7 | AS6: 3.58 | AT6: 33 | AU6: 7 | AV6: 1.51 | AW6: 31 | AX6: 7 | AY6: 2.1 | AZ6: 33 | BA6: 7 | BB6: 2
A7: Algeria | B7: DZA | C7: MENA | D7: 34 | E7: 109 | F7: 8 | G7: 2.318018 | H7: 34 | I7: 107 | J7: 8 | K7: 2.640527 | L7: 36 | M7: 104 | N7: 7 | O7: 2.327238 | P7: 33 | Q7: 116 | R7: 6 | S7: 1.673809 | T7: 33 | U7: 117 | V7: 7 | W7: 1.07623 | X7: 36 | Y7: 104 | Z7: 7 | AA7: 1.481484 | AB7: 35 | AC7: 106 | AD7: 7 | AE7: 2.590262 | AF7: 35 | AG7: 105 | AH7: 6 | AI7: 1.21 | AJ7: 33 | AK7: 112 | AL7: 6 | AM7: 2.32 | AN7: 34 | AO7: 6 | AP7: 2.94 | AQ7: 36 | AR7: 5 | AS7: 1.85 | AT7: 36 | AU7: 5 | AV7: 2.06 | AW7: 36 | AX7: 6 | AY7: 2.8 | AZ7: 34 | BA7: 6 | BB7: 3.3
A8: Angola | B8: AGO | C8: SSA | D8: 32 | E8: 120 | F8: 8 | G8: 2.526907 | H8: 32 | I8: 121 | J8: 8 | K8: 2.804178 | L8: 33 | M8: 121 | N8: 7 | O8: 2.813869 | P8: 33 | Q8: 116 | R8: 7 | S8: 2.807703 | T8: 29 | U8: 136 | V8: 7 | W8: 1.526104 | X8: 27 | Y8: 142 | Z8: 7 | AA8: 2.011135 | AB8: 26 | AC8: 146 | AD8: 7 | AE8: 1.821627 | AF8: 19 | AG8: 165 | AH8: 6 | AI8: 1.31 | AJ8: 19 | AK8: 167 | AL8: 5 | AM8: 1.28 | AN8: 18 | AO8: 4 | AP8: 1.68 | AQ8: 15 | AR8: 5 | AS8: 1.8 | AT8: 19 | AU8: 6 | AV8: 1.71 | AW8: 23 | AX8: 7 | AY8: 2.8 | AZ8: 22 | BA8: 7 | BB8: 1.8
A9: Argentina | B9: ARG | C9: AME | D9: 36 | E9: 104 | F9: 8 | G9: 2.175089 | H9: 37 | I9: 99 | J9: 8 | K9: 3.013744 | L9: 37 | M9: 98 | N9: 8 | O9: 2.046685 | P9: 38 | Q9: 94 | R9: 7 | S9: 2.334808 | T9: 38 | U9: 96 | V9: 8 | W9: 2.099133 | X9: 42 | Y9: 78 | Z9: 8 | AA9: 2.318056 | AB9: 45 | AC9: 66 | AD9: 8 | AE9: 3.288657 | AF9: 40 | AG9: 85 | AH9: 8 | AI9: 2.7 | AJ9: 39 | AK9: 85 | AL9: 8 | AM9: 2.92 | AN9: 36 | AO9: 8 | AP9: 1.76 | AQ9: 32 | AR9: 7 | AS9: 1.84 | AT9: 34 | AU9: 7 | AV9: 2.42 | AW9: 34 | AX9: 8 | AY9: 2.4 | AZ9: 35 | BA9: 8 | BB9: 2.6
A10: Armenia | B10: ARM | C10: ECA | D10: 46 | E10: 65 | F10: 6 | G10: 2.304935 | H10: 47 | I10: 63 | J10: 6 | K10: 2.504353 | L10: 47 | M10: 62 | N10: 6 | O10: 2.543364 | P10: 46 | Q10: 63 | R10: 6 | S10: 2.467806 | T10: 49 | U10: 58 | V10: 6 | W10: 3.764584 | X10: 49 | Y10: 60 | Z10: 6 | AA10: 3.504781 | AB10: 42 | AC10: 77 | AD10: 6 | AE10: 4.310598 | AF10: 35 | AG10: 105 | AH10: 6 | AI10: 4 | AJ10: 35 | AK10: 107 | AL10: 6 | AM10: 3.79 | AN10: 33 | AO10: 6 | AP10: 4.01 | AQ10: 35 | AR10: 5 | AS10: 2.98 | AT10: 37 | AU10: 6 | AV10: 3.69 | AW10: 36 | AX10: 6 | AY10: 3.5 | AZ10: 34 | BA10: 6 | BB10: 2.7
A11: Australia | B11: AUS | C11: AP | D11: 76 | E11: 12 | F11: 9 | G11: 1.429308 | H11: 77 | I11: 10 | J11: 9 | K11: 1.671944 | L11: 75 | M11: 14 | N11: 9 | O11: 1.523523 | P11: 75 | Q11: 13 | R11: 9 | S11: 0.7788845 | T11: 73 | U11: 18 | V11: 9 | W11: 1.626727 | X11: 77 | Y11: 11 | Z11: 9 | AA11: 1.046566 | AB11: 77 | AC11: 12 | AD11: 9 | AE11: 1.317929 | AF11: 77 | AG11: 13 | AH11: 9 | AI11: 1.27 | AJ11: 77 | AK11: 13 | AL11: 9 | AM11: 1.4 | AN11: 79 | AO11: 8 | AP11: 1.27 | AQ11: 79 | AR11: 8 | AS11: 1.5 | AT11: 80 | AU11: 8 | AV11: 1.31 | AW11: 81 | AX11: 8 | AY11: 1.5 | AZ11: 85 | BA11: 8 | BB11: 1.1
A12: Denmark | B12: DNK | C12: WE/EU | D12: 89 | E12: 1 | F12: 8 | G12: 1.882284 | H12: 90 | I12: 1 | J12: 8 | K12: 1.982749 | L12: 90 | M12: 1 | N12: 8 | O12: 1.819265 | P12: 90 | Q12: 1 | R12: 8 | S12: 1.709309 | T12: 88 | U12: 1 | V12: 8 | W12: 1.850507 | X12: 88 | Y12: 1 | Z12: 8 | AA12: 1.775809 | AB12: 87 | AC12: 1 | AD12: 8 | AE12: 2.542474 | AF12: 88 | AG12: 1 | AH12: 8 | AI12: 2.63 | AJ12: 88 | AK12: 2 | AL12: 8 | AM12: 2.75 | AN12: 90 | AO12: 7 | AP12: 2.46 | AQ12: 91 | AR12: 7 | AS12: 2.16 | AT12: 92 | AU12: 7 | AV12: 2.04 | AW12: 91 | AX12: 7 | AY12: 2.2 | AZ12: 90 | BA12: 7 | BB12: 2
A13: Azerbaijan | B13: AZE | C13: ECA | D13: 30 | E13: 130 | F13: 7 | G13: 6.55301 | H13: 22 | I13: 154 | J13: 6 | K13: 2.376703 | L13: 23 | M13: 154 | N13: 6 | O13: 2.462465 | P13: 23 | Q13: 157 | R13: 6 | S13: 2.397118 | T13: 30 | U13: 128 | V13: 7 | W13: 5.524198 | X13: 30 | Y13: 129 | Z13: 7 | AA13: 5.000017 | AB13: 30 | AC13: 126 | AD13: 7 | AE13: 7.161777 | AF13: 25 | AG13: 152 | AH13: 6 | AI13: 4.09 | AJ13: 31 | AK13: 122 | AL13: 7 | AM13: 5.64 | AN13: 30 | AO13: 7 | AP13: 5.13 | AQ13: 29 | AR13: 6 | AS13: 3.25 | AT13: 29 | AU13: 6 | AV13: 3.02 | AW13: 28 | AX13: 6 | AY13: 3.5 | AZ13: 27 | BA13: 6 | BB13: 2.5
A14: Bahamas | B14: BHS | C14: AME | D14: 64 | E14: 29 | F14: 3 | G14: 6.560889 | H14: 65 | I14: 28 | J14: 3 | K14: 6.237338 | L14: 64 | M14: 30 | N14: 3 | O14: 5.47035 | P14: 64 | Q14: 30 | R14: 3 | S14: 5.318037 | T14: 64 | U14: 30 | V14: 3 | W14: 5.631818 | X14: 63 | Y14: 30 | Z14: 3 | AA14: 5.801677 | AB14: 64 | AC14: 29 | AD14: 3 | AE14: 5.825616 | AF14: 65 | AG14: 29 | AH14: 3 | AI14: 5.39 | AJ14: 65 | AK14: 28 | AL14: 3 | AM14: 5.39 | AN14: 66 | AO14: 3 | AP14: 5.2 | AT14: 71 | AU14: 3 | AV14: 0.99 | AW14: 71 | AX14: 3 | AY14: 1 | AZ14: 71 | BA14: 3 | BB14: 1
A15: Bahrain | B15: BHR | C15: MENA | D15: 50 | E15: 56 | F15: 7 | G15: 6.219367 | H15: 53 | I15: 53 | J15: 7 | K15: 6.443612 | L15: 42 | M15: 76 | N15: 6 | O15: 5.329254 | P15: 44 | Q15: 69 | R15: 6 | S15: 6.186327 | T15: 42 | U15: 78 | V15: 6 | W15: 5.19534 | X15: 42 | Y15: 78 | Z15: 6 | AA15: 5.914723 | AB15: 42 | AC15: 77 | AD15: 6 | AE15: 7.645793 | AF15: 36 | AG15: 99 | AH15: 4 | AI15: 1.81 | AJ15: 36 | AK15: 103 | AL15: 4 | AM15: 1.81 | AN15: 43 | AO15: 5 | AP15: 5.96 | AQ15: 51 | AR15: 5 | AS15: 7.86 | AT15: 49 | AU15: 5 | AV15: 6.11 | AW15: 48 | AX15: 5 | AY15: 5.4 | AZ15: 51 | BA15: 5 | BB15: 4.1
A16: Bangladesh | B16: BGD | C16: AP | D16: 24 | E16: 150 | F16: 8 | G16: 1.503636 | H16: 23 | I16: 151 | J16: 8 | K16: 1.464238 | L16: 24 | M16: 149 | N16: 8 | O16: 1.511192 | P16: 25 | Q16: 147 | R16: 8 | S16: 1.927162 | T16: 26 | U16: 147 | V16: 8 | W16: 1.742484 | X16: 26 | Y16: 146 | Z16: 8 | AA16: 1.715685 | AB16: 26 | AC16: 146 | AD16: 8 | AE16: 2.617282 | AF16: 26 | AG16: 149 | AH16: 8 | AI16: 2.63 | AJ16: 28 | AK16: 143 | AL16: 8 | AM16: 3.19 | AN16: 26 | AO16: 7 | AP16: 4.13 | AQ16: 25 | AR16: 7 | AS16: 4.3 | AT16: 25 | AU16: 7 | AV16: 4.23 | AW16: 27 | AX16: 7 | AY16: 4.1 | AZ16: 26 | BA16: 7 | BB16: 4.1
A17: Barbados | B17: BRB | C17: AME | D17: 68 | E17: 24 | F17: 3 | G17: 3.120304 | H17: 68 | I17: 23 | J17: 3 | K17: 3.118658 | L17: 69 | M17: 24 | N17: 3 | O17: 3.366726 | P17: 65 | Q17: 29 | R17: 4 | S17: 3.281295 | T17: 65 | U17: 29 | V17: 4 | W17: 3.065789 | X17: 64 | Y17: 29 | Z17: 4 | AA17: 5.471437 | AB17: 62 | AC17: 30 | AD17: 4 | AE17: 6.05961 | AF17: 68 | AG17: 25 | AH17: 3 | AI17: 3.12 | AJ17: 68 | AK17: 25 | AL17: 3 | AM17: 3.24 | AN17: 61 | AO17: 3 | AP17: 6.91 | AT17: 74 | AU17: 3 | AV17: 8.09 | AW17: 75 | AX17: 3 | AY17: 7.1 | AZ17: 76 | BA17: 3 | BB17: 6.7
A18: Belarus | B18: BLR | C18: ECA | D18: 31 | E18: 124 | F18: 7 | G18: 3.491905 | H18: 33 | I18: 114 | J18: 7 | K18: 3.178518 | L18: 37 | M18: 98 | N18: 7 | O18: 3.337556 | P18: 39 | Q18: 91 | R18: 7 | S18: 3.135647 | T18: 41 | U18: 82 | V18: 8 | W18: 2.345835 | X18: 47 | Y18: 63 | Z18: 7 | AA18: 3.376054 | AB18: 45 | AC18: 66 | AD18: 7 | AE18: 4.20046 | AF18: 44 | AG18: 70 | AH18: 7 | AI18: 3.92 | AJ18: 44 | AK18: 68 | AL18: 7 | AM18: 4.12 | AN18: 40 | AO18: 7 | AP18: 3.93 | AQ18: 32 | AR18: 6 | AS18: 4.37 | AT18: 31 | AU18: 5 | AV18: 4.04 | AW18: 29 | AX18: 5 | AY18: 4 | AZ18: 31 | BA18: 5 | BB18: 3.6
A19: Finland | B19: FIN | C19: WE/EU | D19: 88 | E19: 2 | F19: 8 | G19: 1.806286 | H19: 88 | I19: 2 | J19: 8 | K19: 1.829536 | L19: 87 | M19: 2 | N19: 8 | O19: 1.057962 | P19: 87 | Q19: 2 | R19: 8 | S19: 1.193896 | T19: 88 | U19: 1 | V19: 8 | W19: 1.24828 | X19: 85 | Y19: 3 | Z19: 8 | AA19: 1.748594 | AB19: 86 | AC19: 3 | AD19: 8 | AE19: 2.924511 | AF19: 85 | AG19: 3 | AH19: 8 | AI19: 2.74 | AJ19: 85 | AK19: 3 | AL19: 8 | AM19: 2.84 | AN19: 89 | AO19: 7 | AP19: 1.46 | AQ19: 90 | AR19: 7 | AS19: 1.77 | AT19: 89 | AU19: 7 | AV19: 2.05 | AW19: 89 | AX19: 7 | AY19: 1.7 | AZ19: 90 | BA19: 7 | BB19: 3
A20: Benin | B20: BEN | C20: SSA | D20: 45 | E20: 70 | F20: 6 | G20: 3.401294 | H20: 45 | I20: 69 | J20: 6 | K20: 3.395473 | L20: 43 | M20: 70 | N20: 6 | O20: 3.131058 | P20: 43 | Q20: 72 | R20: 7 | S20: 2.416439 | T20: 42 | U20: 78 | V20: 7 | W20: 2.348642 | X20: 41 | Y20: 83 | Z20: 7 | AA20: 1.797036 | AB20: 41 | AC20: 80 | AD20: 7 | AE20: 2.639245 | AF20: 40 | AG20: 85 | AH20: 6 | AI20: 3.14 | AJ20: 39 | AK20: 85 | AL20: 6 | AM20: 4.17 | AN20: 36 | AO20: 6 | AP20: 3.8 | AQ20: 37 | AR20: 5 | AS20: 4.43 | AT20: 39 | AU20: 4 | AV20: 4.38 | AW20: 36 | AX20: 6 | AY20: 3.4 | AZ20: 36 | BA20: 6 | BB20: 4.3
A21: Belize | B21: BLZ | C21: AME | D21: 36 | E21: 104 | F21: 3 | G21: 1.916648
A22: Bhutan | B22: BTN | C22: AP | D22: 71 | E22: 18 | F22: 4 | G22: 2.063194 | H22: 72 | I22: 18 | J22: 4 | K22: 1.641677 | L22: 68 | M22: 26 | N22: 4 | O22: 2.179297 | P22: 68 | Q22: 25 | R22: 4 | S22: 2.179297 | T22: 68 | U22: 25 | V22: 4 | W22: 2.239852 | X22: 68 | Y22: 24 | Z22: 4 | AA22: 2.387326 | AB22: 68 | AC22: 25 | AD22: 4 | AE22: 2.756646 | AF22: 68 | AG22: 25 | AH22: 4 | AI22: 2.86 | AJ22: 67 | AK22: 26 | AL22: 5 | AM22: 1.83 | AN22: 65 | AO22: 5 | AP22: 2.12 | AQ22: 65 | AR22: 4 | AS22: 2.14 | AT22: 65 | AU22: 4 | AV22: 1.81 | AW22: 63 | AX22: 4 | AY22: 2.6 | AZ22: 63 | BA22: 3 | BB22: 3.6
A23: Bolivia | B23: BOL | C23: AME | D23: 28 | E23: 136 | F23: 7 | G23: 2.99711 | H23: 28 | I23: 133 | J23: 7 | K23: 3.101006 | L23: 29 | M23: 133 | N23: 7 | O23: 2.310445 | P23: 31 | Q23: 126 | R23: 6 | S23: 2.41325 | T23: 30 | U23: 128 | V23: 7 | W23: 1.684876 | X23: 31 | Y23: 124 | Z23: 7 | AA23: 2.048029 | AB23: 31 | AC23: 123 | AD23: 7 | AE23: 2.996561 | AF23: 29 | AG23: 132 | AH23: 7 | AI23: 3.6 | AJ23: 33 | AK23: 112 | AL23: 6 | AM23: 2.98 | AN23: 33 | AO23: 8 | AP23: 2.85 | AQ23: 34 | AR23: 7 | AS23: 3.58 | AT23: 35 | AU23: 7 | AV23: 2.98 | AW23: 34 | AX23: 7 | AY23: 3.7 | AZ23: 34 | BA23: 7 | BB23: 3.7
A24: Bosnia and Herzegovina | B24: BIH | C24: ECA | D24: 34 | E24: 109 | F24: 7 | G24: 2.601689 | H24: 33 | I24: 114 | J24: 7 | K24: 2.043418 | L24: 35 | M24: 108 | N24: 6 | O24: 1.953783 | P24: 34 | Q24: 110 | R24: 7 | S24: 2.184636 | T24: 35 | U24: 110 | V24: 7 | W24: 1.801027 | X24: 35 | Y24: 111 | Z24: 7 | AA24: 1.867208 | AB24: 36 | AC24: 101 | AD24: 7 | AE24: 1.952692 | AF24: 38 | AG24: 89 | AH24: 7 | AI24: 1.86 | AJ24: 38 | AK24: 91 | AL24: 7 | AM24: 2.56 | AN24: 39 | AO24: 7 | AP24: 1.7 | AQ24: 38 | AR24: 6 | AS24: 1.71 | AT24: 39 | AU24: 6 | AV24: 1.15 | AW24: 42 | AX24: 7 | AY24: 2.9 | AZ24: 42 | BA24: 7 | BB24: 2.3
A25: Botswana | B25: BWA | C25: SSA | D25: 58 | E25: 41 | F25: 9 | G25: 1.993262 | H25: 57 | I25: 43 | J25: 9 | K25: 2.406198 | L25: 59 | M25: 39 | N25: 7 | O25: 3.042194 | P25: 60 | Q25: 35 | R25: 8 | S25: 2.630613 | T25: 55 | U25: 45 | V25: 8 | W25: 3.191742 | X25: 60 | Y25: 35 | Z25: 7 | AA25: 2.876193 | AB25: 61 | AC25: 34 | AD25: 7 | AE25: 3.731927 | AF25: 61 | AG25: 34 | AH25: 7 | AI25: 2.76 | AJ25: 61 | AK25: 34 | AL25: 7 | AM25: 2.74 | AN25: 60 | AO25: 6 | AP25: 3.1 | AQ25: 63 | AR25: 6 | AS25: 2.35 | AT25: 63 | AU25: 6 | AV25: 1.93 | AW25: 64 | AX25: 7 | AY25: 1.6 | AZ25: 65 | BA25: 7 | BB25: 1.9
A26: Brazil | B26: BRA | C26: AME | D26: 35 | E26: 107 | F26: 8 | G26: 2.75855 | H26: 34 | I26: 107 | J26: 8 | K26: 2.413868 | L26: 36 | M26: 104 | N26: 8 | O26: 1.466162 | P26: 38 | Q26: 94 | R26: 8 | S26: 1.576192 | T26: 38 | U26: 96 | V26: 8 | W26: 1.613992 | X26: 38 | Y26: 94 | Z26: 8 | AA26: 2.499375 | AB26: 35 | AC26: 106 | AD26: 8 | AE26: 4.060288 | AF26: 35 | AG26: 105 | AH26: 8 | AI26: 4.05 | AJ26: 37 | AK26: 96 | AL26: 8 | AM26: 4.24 | AN26: 40 | AO26: 8 | AP26: 4.34 | AQ26: 38 | AR26: 7 | AS26: 5.29 | AT26: 43 | AU26: 7 | AV26: 4.01 | AW26: 42 | AX26: 8 | AY26: 3.7 | AZ26: 43 | BA26: 8 | BB26: 3.3
A27: Brunei Darussalam | B27: BRN | C27: AP | D27: 63 | E27: 31 | F27: 3 | G27: 5.629506 | X27: 60 | Y27: 35 | Z27: 3 | AA27: 5.585083 | AB27: 60 | AC27: 35 | AD27: 3 | AE27: 6.118152 | AF27: 63 | AG27: 31 | AH27: 3 | AI27: 6.62 | AJ27: 62 | AK27: 32 | AL27: 3 | AM27: 8.72 | AN27: 58 | AO27: 3 | AP27: 8.85 | AW27: 60 | AX27: 3 | AY27: 10.4 | AZ27: 55 | BA27: 3 | BB27: 9.1
A28: Luxembourg | B28: LUX | C28: WE/EU | D28: 78 | E28: 8 | F28: 7 | G28: 2.192617 | H28: 81 | I28: 5 | J28: 7 | K28: 2.000107 | L28: 78 | M28: 9 | N28: 8 | O28: 1.060454 | P28: 77 | Q28: 10 | R28: 8 | S28: 1.083765 | T28: 81 | U28: 9 | V28: 8 | W28: 0.9624774 | X28: 80 | Y28: 9 | Z28: 7 | AA28: 1.503167 | AB28: 80 | AC28: 9 | AD28: 7 | AE28: 1.954564 | AF28: 81 | AG28: 9 | AH28: 7 | AI28: 2.32 | AJ28: 82 | AK28: 8 | AL28: 6 | AM28: 2.08 | AN28: 81 | AO28: 6 | AP28: 1.96 | AQ28: 85 | AR28: 5 | AS28: 1.6 | AT28: 82 | AU28: 6 | AV28: 2.78 | AW28: 80 | AX28: 6 | AY28: 2.9 | AZ28: 80 | BA28: 6 | BB28: 2.8
A29: Burkina Faso | B29: BFA | C29: SSA | D29: 40 | E29: 84 | F29: 7 | G29: 2.493685 | H29: 41 | I29: 82 | J29: 7 | K29: 2.299357 | L29: 41 | M29: 83 | N29: 7 | O29: 1.782614 | P29: 42 | Q29: 77 | R29: 7 | S29: 1.367199 | T29: 42 | U29: 78 | V29: 7 | W29: 1.367199 | X29: 40 | Y29: 86 | Z29: 8 | AA29: 1.622322 | AB29: 40 | AC29: 85 | AD29: 8 | AE29: 2.542852 | AF29: 41 | AG29: 78 | AH29: 8 | AI29: 1.81 | AJ29: 42 | AK29: 74 | AL29: 7 | AM29: 2.18 | AN29: 42 | AO29: 7 | AP29: 2.47 | AQ29: 38 | AR29: 7 | AS29: 2.97 | AT29: 38 | AU29: 7 | AV29: 2.67 | AW29: 38 | AX29: 7 | AY29: 3.9 | AZ29: 38 | BA29: 7 | BB29: 4.4
A30: Burundi | B30: BDI | C30: SSA | D30: 17 | E30: 167 | F30: 5 | G30: 3.391948 | H30: 17 | I30: 165 | J30: 5 | K30: 3.365426 | L30: 20 | M30: 162 | N30: 5 | O30: 1.796819 | P30: 17 | Q30: 171 | R30: 5 | S30: 2.325597 | T30: 19 | U30: 169 | V30: 6 | W30: 3.268247 | X30: 19 | Y30: 165 | Z30: 6 | AA30: 3.737859 | AB30: 19 | AC30: 165 | AD30: 6 | AE30: 4.894006 | AF30: 17 | AG30: 170 | AH30: 5 | AI30: 2.65 | AJ30: 22 | AK30: 157 | AL30: 6 | AM30: 3.29 | AN30: 20 | AO30: 6 | AP30: 1.53 | AQ30: 21 | AR30: 5 | AS30: 2.94 | AT30: 20 | AU30: 5 | AV30: 3.65 | AW30: 21 | AX30: 5 | AY30: 2.6 | AZ30: 19 | BA30: 5 | BB30: 2.8
A31: Cabo Verde | B31: CPV | C31: SSA | D31: 62 | E31: 35 | F31: 5 | G31: 4.233232 | H31: 62 | I31: 35 | J31: 5 | K31: 3.855352 | L31: 64 | M31: 30 | N31: 3 | O31: 3.048059 | P31: 60 | Q31: 35 | R31: 4 | S31: 4.811593 | T31: 58 | U31: 39 | V31: 4 | W31: 2.965474 | X31: 58 | Y31: 41 | Z31: 4 | AA31: 3.722509 | AB31: 58 | AC31: 41 | AD31: 4 | AE31: 4.298384 | AF31: 57 | AG31: 45 | AH31: 4 | AI31: 4.22 | AJ31: 55 | AK31: 48 | AL31: 4 | AM31: 4.19 | AN31: 59 | AO31: 3 | AP31: 5.72 | AQ31: 55 | AR31: 4 | AS31: 6.16 | AT31: 57 | AU31: 4 | AV31: 5.94 | AW31: 58 | AX31: 4 | AY31: 4.8 | AZ31: 60 | BA31: 4 | BB31: 3.8
A32: Cambodia | B32: KHM | C32: AP | D32: 20 | E32: 163 | F32: 7 | G32: 3.044885 | H32: 21 | I32: 158 | J32: 7 | K32: 2.863744 | L32: 22 | M32: 158 | N32: 7 | O32: 2.904808 | P32: 24 | Q32: 150 | R32: 8 | S32: 2.782431 | T32: 23 | U32: 157 | V32: 8 | W32: 2.842698 | X32: 21 | Y32: 160 | Z32: 8 | AA32: 2.322713 | AB32: 20 | AC32: 162 | AD32: 8 | AE32: 3.409514 | AF32: 20 | AG32: 161 | AH32: 8 | AI32: 2.58 | AJ32: 21 | AK32: 161 | AL32: 8 | AM32: 2.43 | AN32: 21 | AO32: 8 | AP32: 2.82 | AQ32: 21 | AR32: 7 | AS32: 3.87 | AT32: 21 | AU32: 7 | AV32: 2.25 | AW32: 20 | AX32: 7 | AY32: 3 | AZ32: 22 | BA32: 7 | BB32: 3.1
A33: Cameroon | B33: CMR | C33: SSA | D33: 26 | E33: 142 | F33: 9 | G33: 1.694514 | H33: 26 | I33: 140 | J33: 9 | K33: 1.759728 | L33: 27 | M33: 140 | N33: 9 | O33: 1.652038 | P33: 26 | Q33: 142 | R33: 9 | S33: 1.370248 | T33: 27 | U33: 144 | V33: 9 | W33: 1.366871 | X33: 25 | Y33: 149 | Z33: 9 | AA33: 1.364944 | AB33: 25 | AC33: 153 | AD33: 9 | AE33: 2.424488 | AF33: 25 | AG33: 152 | AH33: 9 | AI33: 2.43 | AJ33: 25 | AK33: 153 | AL33: 9 | AM33: 2.58 | AN33: 26 | AO33: 9 | AP33: 3.04 | AQ33: 27 | AR33: 8 | AS33: 3.26 | AT33: 27 | AU33: 8 | AV33: 2.87 | AW33: 25 | AX33: 8 | AY33: 2.9 | AZ33: 26 | BA33: 8 | BB33: 3.5
A34: Canada | B34: CAN | C34: AME | D34: 75 | E34: 16 | F34: 8 | G34: 1.959374 | H34: 75 | I34: 15 | J34: 8 | K34: 1.950074 | L34: 76 | M34: 12 | N34: 8 | O34: 1.725637 | P34: 74 | Q34: 14 | R34: 8 | S34: 2.123417 | T34: 74 | U34: 13 | V34: 8 | W34: 2.299962 | X34: 77 | Y34: 11 | Z34: 8 | AA34: 1.771133 | AB34: 77 | AC34: 12 | AD34: 8 | AE34: 2.796791 | AF34: 81 | AG34: 9 | AH34: 8 | AI34: 2.16 | AJ34: 82 | AK34: 8 | AL34: 8 | AM34: 1.49 | AN34: 82 | AO34: 7 | AP34: 2.03 | AQ34: 83 | AR34: 7 | AS34: 1.63 | AT34: 81 | AU34: 7 | AV34: 2.45 | AW34: 81 | AX34: 7 | AY34: 2.4 | AZ34: 84 | BA34: 7 | BB34: 2.2
A35: Central African Republic | B35: CAF | C35: SSA | D35: 24 | E35: 150 | F35: 5 | G35: 2.094887 | H35: 24 | I35: 149 | J35: 5 | K35: 1.565208 | L35: 24 | M35: 149 | N35: 5 | O35: 0.9885881 | P35: 24 | Q35: 150 | R35: 5 | S35: 0.8079345 | T35: 24 | U35: 154 | V35: 5 | W35: 0.9885881 | X35: 26 | Y35: 146 | Z35: 5 | AA35: 0.9326452 | AB35: 25 | AC35: 153 | AD35: 5 | AE35: 1.428002 | AF35: 26 | AG35: 149 | AH35: 5 | AI35: 1.14 | AJ35: 23 | AK35: 156 | AL35: 5 | AM35: 3.28 | AN35: 20 | AO35: 4 | AP35: 4.04 | AQ35: 24 | AR35: 4 | AS35: 1.44 | AT35: 24 | AU35: 4 | AV35: 1.33 | AW35: 25 | AX35: 4 | AY35: 5.4 | AZ35: 26 | BA35: 4 | BB35: 2.4
A36: Chad | B36: TCD | C36: SSA | D36: 22 | E36: 157 | F36: 6 | G36: 3.6321 | H36: 21 | I36: 158 | J36: 6 | K36: 3.012614 | L36: 20 | M36: 162 | N36: 6 | O36: 2.155059 | P36: 19 | Q36: 167 | R36: 6 | S36: 1.513127 | T36: 20 | U36: 164 | V36: 6 | W36: 1.885957 | X36: 21 | Y36: 160 | Z36: 6 | AA36: 1.710202 | AB36: 20 | AC36: 162 | AD36: 6 | AE36: 2.451336 | AF36: 19 | AG36: 165 | AH36: 6 | AI36: 2.94 | AJ36: 20 | AK36: 165 | AL36: 6 | AM36: 2.73 | AN36: 20 | AO36: 5 | AP36: 2.67 | AQ36: 22 | AR36: 5 | AS36: 2.35 | AT36: 22 | AU36: 5 | AV36: 2.95 | AW36: 19 | AX36: 5 | AY36: 3.8 | AZ36: 19 | BA36: 5 | BB36: 2.5
A37: Chile | B37: CHL | C37: AME | D37: 63 | E37: 31 | F37: 8 | G37: 2.333968 | H37: 63 | I37: 32 | J37: 8 | K37: 2.296134 | L37: 66 | M37: 29 | N37: 9 | O37: 1.540951 | P37: 67 | Q37: 27 | R37: 9 | S37: 1.34103 | T37: 67 | U37: 27 | V37: 9 | W37: 1.32958 | X37: 67 | Y37: 25 | Z37: 9 | AA37: 1.225991 | AB37: 67 | AC37: 26 | AD37: 9 | AE37: 2.552611 | AF37: 67 | AG37: 27 | AH37: 9 | AI37: 1.88 | AJ37: 67 | AK37: 26 | AL37: 9 | AM37: 2.03 | AN37: 66 | AO37: 8 | AP37: 2.65 | AQ37: 70 | AR37: 8 | AS37: 2.15 | AT37: 73 | AU37: 8 | AV37: 1.74 | AW37: 71 | AX37: 9 | AY37: 1.8 | AZ37: 72 | BA37: 9 | BB37: 2.1
A38: China | B38: CHN | C38: AP | D38: 43 | E38: 76 | F38: 8 | G38: 1.302773 | H38: 43 | I38: 76 | J38: 8 | K38: 1.635139 | L38: 42 | M38: 76 | N38: 8 | O38: 1.644832 | P38: 45 | Q38: 65 | R38: 9 | S38: 1.811471 | T38: 45 | U38: 66 | V38: 9 | W38: 1.768843 | X38: 42 | Y38: 78 | Z38: 8 | AA38: 1.630193 | AB38: 41 | AC38: 80 | AD38: 8 | AE38: 2.100923 | AF38: 39 | AG38: 87 | AH38: 8 | AI38: 2.02 | AJ38: 41 | AK38: 77 | AL38: 9 | AM38: 1.96 | AN38: 40 | AO38: 8 | AP38: 2.39 | AQ38: 37 | AR38: 8 | AS38: 2.34 | AT38: 36 | AU38: 8 | AV38: 2.17 | AW38: 40 | AX38: 9 | AY38: 2.9 | AZ38: 39 | BA38: 9 | BB38: 2.9
A39: Colombia | B39: COL | C39: AME | D39: 37 | E39: 99 | F39: 8 | G39: 2.224609 | H39: 39 | I39: 92 | J39: 8 | K39: 2.589917 | L39: 40 | M39: 87 | N39: 8 | O39: 1.423581 | P39: 39 | Q39: 91 | R39: 8 | S39: 1.379437 | T39: 39 | U39: 87 | V39: 8 | W39: 1.454743 | X39: 39 | Y39: 92 | Z39: 8 | AA39: 1.588306 | AB39: 37 | AC39: 96 | AD39: 8 | AE39: 2.493945 | AF39: 36 | AG39: 99 | AH39: 8 | AI39: 2.51 | AJ39: 37 | AK39: 96 | AL39: 8 | AM39: 2.77 | AN39: 37 | AO39: 8 | AP39: 2.27 | AQ39: 37 | AR39: 7 | AS39: 1.94 | AT39: 37 | AU39: 7 | AV39: 1.68 | AW39: 36 | AX39: 7 | AY39: 2 | AZ39: 36 | BA39: 7 | BB39: 2.6
... A50: Djibouti | B50: DJI | C50: SSA | D50: 31 | E50: 124 | F50: 5 | G50: 1.951494 | H50: 31 | I50: 127 | J50: 5 | K50: 1.978427 | L50: 30 | M50: 130 | N50: 5 | O50: 1.711382 | P50: 30 | Q50: 130 | R50: 5 | S50: 1.737748 | T50: 30 | U50: 128 | V50: 5 | W50: 1.680318 | X50: 27 | Y50: 142 | Z50: 5 | AA50: 1.529401 | AB50: 30 | AC50: 126 | AD50: 5 | AE50: 4.276603 | AF50: 31 | AG50: 124 | AH50: 4 | AI50: 5.38 | AJ50: 31 | AK50: 122 | AL50: 4 | AM50: 5.32 | AN50: 30 | AO50: 3 | AP50: 8.23 | AQ50: 34 | AR50: 3 | AS50: 9.07 | AT50: 34 | AU50: 3 | AV50: 9.1 | AW50: 36 | AX50: 3 | AY50: 8.6 | AZ50: 36 | BA50: 3 | BB50: 8.6
A51: Dominica | B51: DMA | C51: AME | D51: 60 | E51: 37 | F51: 3 | G51: 1.746044 | H51: 60 | I51: 36 | J51: 3 | K51: 1.738621 | L51: 56 | M51: 42 | N51: 3 | O51: 1.914757 | P51: 55 | Q51: 45 | R51: 3 | S51: 1.896461 | T51: 55 | U51: 45 | V51: 3 | W51: 1.976205 | X51: 55 | Y51: 48 | Z51: 3 | AA51: 1.976205 | AB51: 55 | AC51: 48 | AD51: 3 | AE51: 2.164824 | AF51: 57 | AG51: 45 | AH51: 3 | AI51: 2.55 | AJ51: 57 | AK51: 42 | AL51: 3 | AM51: 2.55 | AN51: 59 | AO51: 3 | AP51: 0.85 | AT51: 58 | AU51: 3 | AV51: 2.34 | AW51: 58 | AX51: 3 | AY51: 2.3 | AZ51: 58 | BA51: 3 | BB51: 2.3
...

Sheet CPI 2025 Regional Averages
A1: Corruption Perceptions Index 2025: Averages by Region
A2: EMBARGOED UNTIL 10.02.2026
A4: Region | B4: Average of CPI score 2025 | C4: N | D4: Average of CPI score 2024 | E4: N | F4: Average of CPI score 2023 | G4: N | H4: Average of CPI score 2022 | I4: N | J4: Average of CPI score 2021 | K4: N | L4: Average of CPI score 2020 | M4: N | N4: Average of CPI score 2019 | O4: N | P4: Average of CPI score 2018 | Q4: N | R4: Average of CPI score 2017 | S4: N | T4: Average of CPI score 2016 | U4: N
A5: AME | B5: 42 | C5: 33 | D5: 42 | E5: 32 | F5: 43 | G5: 32 | H5: 42.96875 | I5: 32 | J5: 43.125 | K5: 32 | L5: 43.375 | M5: 32 | N5: 43.375 | O5: 32 | P5: 43.71875 | Q5: 32 | R5: 44.1875 | S5: 32 | T5: 44.09375 | U5: 32
A6: AP | B6: 45 | C6: 32 | D6: 44 | E6: 31 | F6: 45 | G6: 31 | H6: 45.129032 | I6: 31 | J6: 45.096774 | K6: 31 | L6: 45.290323 | M6: 31 | N6: 44.870968 | O6: 31 | P6: 44.387097 | Q6: 31 | R6: 44.387097 | S6: 31 | T6: 43.866667 | U6: 30
A7: ECA | B7: 34 | C7: 19 | D7: 35 | E7: 19 | F7: 35 | G7: 19 | H7: 35.210526 | I7: 19 | J7: 35.684211 | K7: 19 | L7: 35.947368 | M7: 19 | N7: 34.789474 | O7: 19 | P7: 34.526316 | Q7: 19 | R7: 34.473684 | S7: 19 | T7: 34.315789 | U7: 19
A8: MENA | B8: 39 | C8: 18 | D8: 39 | E8: 18 | F8: 38 | G8: 18 | H8: 37.5 | I8: 18 | J8: 38.722222 | K8: 18 | L8: 39.111111 | M8: 18 | N8: 39 | O8: 18 | P8: 38.555556 | Q8: 18 | R8: 37.888889 | S8: 18 | T8: 37.5 | U8: 18
A9: SSA | B9: 32 | C9: 49 | D9: 33 | E9: 49 | F9: 33 | G9: 49 | H9: 32.387755 | I9: 49 | J9: 32.510204 | K9: 49 | L9: 32.306122 | M9: 49 | N9: 32.244898 | O9: 49 | P9: 32.244898 | Q9: 49 | R9: 32.020408 | S9: 49 | T9: 31.456522 | U9: 46
A10: WE/EU | B10: 64 | C10: 31 | D10: 64 | E10: 31 | F10: 65 | G10: 31 | H10: 65.516129 | I10: 31 | J10: 65.870968 | K10: 31 | L10: 65.806452 | M10: 31 | N10: 66.064516 | O10: 31 | P10: 66.322581 | Q10: 31 | R10: 66.354839 | S10: 31 | T10: 66.387097 | U10: 31
A11: TOTAL | B11: 42 | C11: 182 | D11: 43 | E11: 180 | F11: 43 | G11: 180 | H11: 42.977778 | I11: 180 | J11: 43.266667 | K11: 180 | L11: 43.344444 | M11: 180 | N11: 43.166667 | O11: 180 | P11: 43.116667 | Q11: 180 | R11: 43.072222 | S11: 180 | T11: 42.948864 | U11: 176
A14: Regime type* | B14: Average of CPI score 2025 | C14: N
A15: Full democracy | B15: 71 | C15: 25
A16: Flawed democracy | B16: 47 | C16: 46
A17: Hybrid regime | B17: 36 | C17: 36
A18: Authoritarian regime | B18: 29 | C18: 59
A19: TOTAL | C19: 166
A21: * Based on the Economist Intelligence Unit's democracy classification for the years 2024 and 2025. Data available at: https://ourworldindata.org/grapher/political-regime-eiu
A24: Civic Space* | B24: Average of CPI score 2024 | C24: N
A25: Open | B25: 67 | C25: 28
A26: Narrowed | B26: 50 | C26: 39
A27: Obstructed | B27: 38 | C27: 34
A28: Repressed | B28: 32 | C28: 50
A29: Closed | B29: 30 | C29: 29
A30: TOTAL | C30: 177
A32: * Based on the CIVICUS Monitor classification for the year 2024. Data avilalbe at: https://monitor.civicus.org/data/download/

Sheet Significant Changes since 2012 
A1: Corruption Perceptions Index 2025: Statistically Significant Changes since 2012
A2: EMBARGOED UNTIL 10.02.2026
A4: Country | B4: ISO3 | C4: Region | D4: CPI2025 | E4: Reference Year | F4: CPI score for reference year | G4: Direction of Change | H4: Change | I4: Category
A5: Argentina | B5: ARG | C5: AME | D5: 36 | E5: 2019 | F5: 45 | G5: -9 | H5: -9 since 2019 | I5: Decliner
A6: Australia | B6: AUS | C6: AP | D6: 76 | E6: 2012 | F6: 85 | G6: -9 | H6: -9 since 2012 | I6: Decliner
A7: Austria | B7: AUT | C7: WE/EU | D7: 69 | E7: 2019 | F7: 77 | G7: -8 | H7: -8 since 2019 | I7: Decliner
A8: Belarus | B8: BLR | C8: ECA | D8: 31 | E8: 2020 | F8: 47 | G8: -16 | H8: -16 since 2020 | I8: Decliner
A9: Belgium | B9: BEL | C9: WE/EU | D9: 69 | E9: 2016 | F9: 77 | G9: -8 | H9: -8 since 2016 | I9: Decliner
A10: Bosnia and Herzegovina | B10: BIH | C10: ECA | D10: 34 | E10: 2012 | F10: 42 | G10: -8 | H10: -8 since 2012 | I10: Decliner
A11: Botswana | B11: BWA | C11: SSA | D11: 58 | E11: 2012 | F11: 65 | G11: -7 | H11: -7 since 2012 | I11: Decliner
A12: Canada | B12: CAN | C12: AME | D12: 75 | E12: 2012 | F12: 84 | G12: -9 | H12: -9 since 2012 | I12: Decliner
A13: Chile | B13: CHL | C13: AME | D13: 63 | E13: 2014 | F13: 73 | G13: -10 | H13: -10 since 2014 | I13: Decliner
A14: Cuba | B14: CUB | C14: AME | D14: 40 | E14: 2019 | F14: 48 | G14: -8 | H14: -8 since 2019 | I14: Decliner
A15: Cyprus | B15: CYP | C15: WE/EU | D15: 55 | E15: 2012 | F15: 66 | G15: -11 | H15: -11 since 2012 | I15: Decliner
A16: El Salvador | B16: SLV | C16: AME | D16: 32 | E16: 2015 | F16: 39 | G16: -7 | H16: -7 since 2015 | I16: Decliner
... A27: Madagascar | B27: MDG | C27: SSA | D27: 25 | E27: 2012 | F27: 32 | G27: -7 | H27: -7 since 2012 | I27: Decliner
A28: Mali | B28: MLI | C28: SSA | D28: 28 | E28: 2015 | F28: 35 | G28: -7 | H28: -7 since 2015 | I28: Decliner | M28: Significant changes since 2012 | O28: Significant changes since 2016
A29: Malta | B29: MLT | C29: WE/EU | D29: 49 | E29: 2015 | F29: 60 | G29: -11 | H29: -11 since 2015 | I29: Decliner | L29: Region | M29: Decliner | N29: Improver | O29: Decliner | P29: Improver
A30: Mauritius | B30: MUS | C30: SSA | D30: 48 | E30: 2012 | F30: 57 | G30: -9 | H30: -9 since 2012 | I30: Decliner | L30: AME | M30: 12 | N30: 2 | O30: 8 | P30: 1
A31: Mexico | B31: MEX | C31: AME | D31: 27 | E31: 2014 | F31: 35 | G31: -8 | H31: -8 since 2014 | I31: Decliner | L31: AP | M31: 6 | N31: 8 | O31: 3 | P31: 5
A32: Mongolia | B32: MNG | C32: AP | D32: 31 | E32: 2015 | F32: 39 | G32: -8 | H32: -8 since 2015 | I32: Decliner | L32: ECA | M32: 6 | N32: 7 | O32: 5 | P32: 4
A33: Mozambique | B33: MOZ | C33: SSA | D33: 21 | E33: 2015 | F33: 31 | G33: -10 | H33: -10 since 2015 | I33: Decliner | L33: MENA | M33: 3 | N33: 0 | O33: 0 | P33: 0
A34: Myanmar | B34: MMR | C34: AP | D34: 16 | E34: 2017 | F34: 30 | G34: -14 | H34: -14 since 2017 | I34: Decliner | L34: SSA | M34: 10 | N34: 7 | O34: 4 | P34: 3
A35: New Zealand | B35: NZL | C35: AP | D35: 81 | E35: 2015 | F35: 91 | G35: -10 | H35: -10 since 2015 | I35: Decliner | L35: WE/EU | M35: 13 | N35: 7 | O35: 8 | P35: 3
A36: Nicaragua | B36: NIC | C36: AME | D36: 14 | E36: 2012 | F36: 29 | G36: -15 | H36: -15 since 2012 | I36: Decliner | L36: TOTAL | M36: 50 | N36: 31 | O36: 28 | P36: 16
A37: Norway | B37: NOR | C37: WE/EU | D37: 81 | E37: 2015 | F37: 88 | G37: -7 | H37: -7 since 2015 | I37: Decliner
A38: Peru | B38: PER | C38: AME | D38: 30 | E38: 2020 | F38: 38 | G38: -8 | H38: -8 since 2020 | I38: Decliner
A39: Poland | B39: POL | C39: WE/EU | D39: 53 | E39: 2015 | F39: 63 | G39: -10 | H39: -10 since 2015 | I39: Decliner
A40: Portugal | B40: PRT | C40: WE/EU | D40: 56 | E40: 2018 | F40: 64 | G40: -8 | H40: -8 since 2018 | I40: Decliner
A41: Russia | B41: RUS | C41: ECA | D41: 22 | E41: 2020 | F41: 30 | G41: -8 | H41: -8 since 2020 | I41: Decliner
A42: Serbia | B42: SRB | C42: ECA | D42: 33 | E42: 2016 | F42: 42 | G42: -9 | H42: -9 since 2016 | I42: Decliner
A43: South Sudan | B43: SSD | C43: SSA | D43: 9 | E43: 2015 | F43: 15 | G43: -6 | H43: -6 since 2015 | I43: Decliner
A44: Spain | B44: ESP | C44: WE/EU | D44: 55 | E44: 2012 | F44: 65 | G44: -10 | H44: -10 since 2012 | I44: Decliner
A45: Sri Lanka | B45: LKA | C45: AP | D45: 35 | E45: 2012 | F45: 40 | G45: -5 | H45: -5 since 2012 | I45: Decliner
A46: Sweden | B46: SWE | C46: WE/EU | D46: 80 | E46: 2015 | F46: 89 | G46: -9 | H46: -9 since 2015 | I46: Decliner
A47: Syria | B47: SYR | C47: MENA | D47: 15 | E47: 2012 | F47: 26 | G47: -11 | H47: -11 since 2012 | I47: Decliner
A48: Thailand | B48: THA | C48: AP | D48: 33 | E48: 2015 | F48: 38 | G48: -5 | H48: -5 since 2015 | I48: Decliner
... A85: Vietnam | B85: VNM | C85: AP | D85: 41 | E85: 2015 | F85: 31 | G85: 10 | H85: 10 since 2015 | I85: Improver

Sheet CPI 2025 Trends
A1: Corruption Perceptions Index 2024: 1-, 5- and 10-year trends
A2: EMBARGOED UNTIL 10.02.2026
E4: 1-year trend | G4: 5-year trend | I4: 10-year trend
A5: Country / Territory | B5: ISO3 | C5: Region | D5: CPI score 2025 | E5: CPI score 2024 | F5: Change since 2024 | G5: CPI score 2021 | H5: Change since 2021 | I5: CPI score 2016 | J5: Change since 2016
A6: Afghanistan | B6: AFG | C6: AP | D6: 16 | E6: 17 | F6: -1 | G6: 16 | H6: 0 | I6: 15 | J6: 1
A7: Albania | B7: ALB | C7: ECA | D7: 39 | E7: 42 | F7: -3 | G7: 35 | H7: 4 | I7: 39 | J7: 0
A8: Algeria | B8: DZA | C8: MENA | D8: 34 | E8: 34 | F8: 0 | G8: 33 | H8: 1 | I8: 34 | J8: 0
A9: Angola | B9: AGO | C9: SSA | D9: 32 | E9: 32 | F9: 0 | G9: 29 | H9: 3 | I9: 18 | J9: 14
A10: Argentina | B10: ARG | C10: AME | D10: 36 | E10: 37 | F10: -1 | G10: 38 | H10: -2 | I10: 36 | J10: 0
A11: Armenia | B11: ARM | C11: ECA | D11: 46 | E11: 47 | F11: -1 | G11: 49 | H11: -3 | I11: 33 | J11: 13
A12: Australia | B12: AUS | C12: AP | D12: 76 | E12: 77 | F12: -1 | G12: 73 | H12: 3 | I12: 79 | J12: -3
A13: Austria | B13: AUT | C13: WE/EU | D13: 69 | E13: 67 | F13: 2 | G13: 74 | H13: -5 | I13: 75 | J13: -6
A14: Azerbaijan | B14: AZE | C14: ECA | D14: 30 | E14: 22 | F14: 8 | G14: 30 | H14: 0 | I14: 30 | J14: 0
A15: Bahamas | B15: BHS | C15: AME | D15: 64 | E15: 65 | F15: -1 | G15: 64 | H15: 0 | I15: 66 | J15: -2
A16: Bahrain | B16: BHR | C16: MENA | D16: 50 | E16: 53 | F16: -3 | G16: 42 | H16: 8 | I16: 43 | J16: 7
A17: Bangladesh | B17: BGD | C17: AP | D17: 24 | E17: 23 | F17: 1 | G17: 26 | H17: -2 | I17: 26 | J17: -2
... A20: Belgium | B20: BEL | C20: WE/EU | D20: 69 | E20: 69 | F20: 0 | G20: 73 | H20: -4 | I20: 77 | J20: -8
A21: Belize | B21: BLZ | C21: AME | D21: 36 | E21: - | G21: - | I21: -
A22: Benin | B22: BEN | C22: SSA | D22: 45 | E22: 45 | F22: 0 | G22: 42 | H22: 3 | I22: 36 | J22: 9
A23: Bhutan | B23: BTN | C23: AP | D23: 71 | E23: 72 | F23: -1 | G23: 68 | H23: 3 | I23: 65 | J23: 6
A24: Bolivia | B24: BOL | C24: AME | D24: 28 | E24: 28 | F24: 0 | G24: 30 | H24: -2 | I24: 33 | J24: -5
A25: Bosnia and Herzegovina | B25: BIH | C25: ECA | D25: 34 | E25: 33 | F25: 1 | G25: 35 | H25: -1 | I25: 39 | J25: -5
A26: Botswana | B26: BWA | C26: SSA | D26: 58 | E26: 57 | F26: 1 | G26: 55 | H26: 3 | I26: 60 | J26: -2
A27: Brazil | B27: BRA | C27: AME | D27: 35 | E27: 34 | F27: 1 | G27: 38 | H27: -3 | I27: 40 | J27: -5
A28: Bulgaria | B28: BGR | C28: WE/EU | D28: 40 | E28: 43 | F28: -3 | G28: 42 | H28: -2 | I28: 41 | J28: -1
A29: Burkina Faso | B29: BFA | C29: SSA | D29: 40 | E29: 41 | F29: -1 | G29: 42 | H29: -2 | I29: 42 | J29: -2
A30: Burundi | B30: BDI | C30: SSA | D30: 17 | E30: 17 | F30: 0 | G30: 19 | H30: -2 | I30: 20 | J30: -3
A31: Cabo Verde | B31: CPV | C31: SSA | D31: 62 | E31: 62 | F31: 0 | G31: 58 | H31: 4 | I31: 59 | J31: 3
A32: Cambodia | B32: KHM | C32: AP | D32: 20 | E32: 21 | F32: -1 | G32: 23 | H32: -3 | I32: 21 | J32: -1
A33: Cameroon | B33: CMR | C33: SSA | D33: 26 | E33: 26 | F33: 0 | G33: 27 | H33: -1 | I33: 26 | J33: 0
... A55: El Salvador | B55: SLV | C55: AME | D55: 32 | E55: 30 | F55: 2 | G55: 34 | H55: -2 | I55: 36 | J55: -4
A56: Equatorial Guinea | B56: GNQ | C56: SSA | D56: 15 | E56: 13 | F56: 2 | G56: 17 | H56: -2 | I56: -
A57: Eritrea | B57: ERI | C57: SSA | D57: 13 | E57: 13 | F57: 0 | G57: 22 | H57: -9 | I57: 18 | J57: -5
A58: Estonia | B58: EST | C58: WE/EU | D58: 76 | E58: 76 | F58: 0 | G58: 74 | H58: 2 | I58: 70 | J58: 6
A59: Eswatini | B59: SWZ | C59: SSA | D59: 23 | E59: 27 | F59: -4 | G59: 32 | H59: -9 | I59: -
A60: Ethiopia | B60: ETH | C60: SSA | D60: 38 | E60: 37 | F60: 1 | G60: 39 | H60: -1 | I60: 34 | J60: 4
A61: Fiji | B61: FJI | C61: AP | D61: 55 | E61: 55 | F61: 0 | G61: 55 | H61: 0 | I61: -
A62: Finland | B62: FIN | C62: WE/EU | D62: 88 | E62: 88 | F62: 0 | G62: 88 | H62: 0 | I62: 89 | J62: -1
A63: France | B63: FRA | C63: WE/EU | D63: 66 | E63: 67 | F63: -1 | G63: 71 | H63: -5 | I63: 69 | J63: -3
A64: Gabon | B64: GAB | C64: SSA | D64: 29 | E64: 27 | F64: 2 | G64: 31 | H64: -2 | I64: 35 | J64: -6
...

Sheet CPI Historical
A1: Corruption Perceptions Index 2024: Historical Results
A2: EMBARGOED UNTIL 10.02.2026
A4: Country / Territory | B4: ISO3 | C4: Year | D4: Region | E4: CPI score | F4: Rank | G4: Standard error | H4: Number of sources | I4: Lower CI | J4: Upper CI | K4: African Development Bank CPIA | L4: Bertelsmann Foundation Sustainable Governance Index | M4: Bertelsmann Foundation Transformation Index | N4: Economist Intelligence Unit Country Ratings | O4: Freedom House Nations in Transit | P4: Global Insights Country Risk Ratings | Q4: IMD World Competitiveness Yearbook | R4: PERC Asia Risk Guide | S4: PRS International Country Risk Guide | T4: Varieties of Democracy Project | U4: World Bank CPIA | V4: World Economic Forum EOS | W4: World Justice Project Rule of Law Index | X4: Transparency International Bribe Payers Survey
A5: Afghanistan | B5: AFG | C5: 2012 | D5: AP | E5: 8 | F5: 174 | G5: 3.3 | H5: 3 | I5: 2 | J5: 13 | M5: 10 | P5: 1 | U5: 12
A6: Afghanistan | B6: AFG | C6: 2013 | D6: AP | E6: 8 | F6: 175 | G6: 3.3 | H6: 3 | I6: 3 | J6: 13 | M6: 10 | P6: 1 | U6: 12
A7: Afghanistan | B7: AFG | C7: 2014 | D7: AP | E7: 12 | F7: 172 | G7: 1.29 | H7: 4 | I7: 10 | J7: 14 | M7: 10 | P7: 11 | U7: 12 | W7: 16
A8: Afghanistan | B8: AFG | C8: 2015 | D8: AP | E8: 11 | F8: 166 | G8: 3.49 | H8: 4 | I8: 5 | J8: 17 | M8: 19 | P8: 11 | U8: 12 | W8: 2
A9: Afghanistan | B9: AFG | C9: 2016 | D9: AP | E9: 15 | F9: 169 | G9: 1.74 | H9: 5 | I9: 12 | J9: 17 | M9: 20 | P9: 10 | T9: 16 | U9: 13 | W9: 13
A10: Afghanistan | B10: AFG | C10: 2017 | D10: AP | E10: 15 | F10: 177 | G10: 1.39 | H10: 5 | I10: 13 | J10: 17 | M10: 17 | P10: 10 | T10: 15 | U10: 18 | W10: 16
A11: Afghanistan | B11: AFG | C11: 2018 | D11: AP | E11: 16 | F11: 172 | G11: 1.41 | H11: 5 | I11: 14 | J11: 18 | M11: 17 | P11: 10 | T11: 17 | U11: 18 | W11: 16
A12: Afghanistan | B12: AFG | C12: 2019 | D12: AP | E12: 16 | F12: 173 | G12: 2.554536 | H12: 5 | I12: 11.81056 | J12: 20.18944 | M12: 25 | P12: 10 | T12: 13 | U12: 18 | W12: 14
A13: Afghanistan | B13: AFG | C13: 2020 | D13: AP | E13: 19 | F13: 165 | G13: 2.440014 | H13: 5 | I13: 14.99838 | J13: 23.00162 | M13: 25 | P13: 10 | T13: 26 | U13: 18 | W13: 15
A14: Afghanistan | B14: AFG | C14: 2021 | D14: AP | E14: 16 | F14: 174 | G14: 2.12416 | H14: 5 | I14: 12.50576 | J14: 19.49424 | M14: 24.86647 | P14: 10.21805 | T14: 12.33825 | U14: 18.44911 | W14: 14.0221
A15: Afghanistan | B15: AFG | C15: 2022 | D15: AP | E15: 24 | F15: 150 | G15: 6.299999 | H15: 4 | I15: 13.668 | J15: 34.332 | M15: 25 | P15: 10 | T15: 43 | W15: 16
A16: Afghanistan | B16: AFG | C16: 2023 | D16: AP | E16: 20 | F16: 162 | G16: 6.244771 | H16: 5 | I16: 9.758576 | J16: 30.24142 | M16: 24.86647 | P16: 10.21805 | T16: 46.33829 | U16: 1.786336 | W16: 14.92038
A17: Afghanistan | B17: AFG | C17: 2024 | D17: AP | E17: 17 | F17: 165 | G17: 5.759683 | H17: 5 | I17: 7.55412 | J17: 26.44588 | M17: 25.63946 | P17: 5.883308 | T17: 39.52382 | U17: 0 | W17: 15.82653
A18: Afghanistan | B18: AFG | C18: 2025 | D18: =VLOOKUP(B18,'CPI Timeseries 2012 - 2025'!B:C,2,0) -> AP | E18: 16 | F18: 169 | G18: 4.225913 | H18: 5 | I18: 9.069504 | J18: 22.9305 | M18: 25.64426 | P18: 5.806674 | T18: 29.26165 | U18: 3.235348 | W18: 15.80222
A19: Albania | B19: ALB | C19: 2012 | D19: ECA | E19: 33 | F19: 113 | G19: 2 | H19: 7 | I19: 30 | J19: 36 | M19: 36 | N19: 38 | O19: 39 | P19: 32 | S19: 31 | V19: 32 | W19: 23
A20: Albania | B20: ALB | C20: 2013 | D20: ECA | E20: 31 | F20: 116 | G20: 2.1 | H20: 7 | I20: 28 | J20: 34 | M20: 32 | N20: 38 | O20: 37 | P20: 32 | S20: 31 | V20: 23 | W20: 23
A21: Albania | B21: ALB | C21: 2014 | D21: ECA | E21: 33 | F21: 110 | G21: 1.51 | H21: 7 | I21: 31 | J21: 35 | M21: 32 | N21: 38 | O21: 37 | P21: 32 | S21: 31 | V21: 37 | W21: 26
A22: Albania | B22: ALB | C22: 2015 | D22: ECA | E22: 36 | F22: 88 | G22: 3.5799999 | H22: 7 | I22: 30 | J22: 42 | M22: 36 | N22: 38 | O22: 37 | P22: 32 | S22: 41 | V22: 49 | W22: 18
A23: Albania | B23: ALB | C23: 2016 | D23: ECA | E23: 39 | F23: 83 | G23: 1.99 | H23: 7 | I23: 36 | J23: 42 | M23: 36 | N23: 37 | O23: 41 | P23: 47 | S23: 41 | V23: 41 | W23: 30
A24: Albania | B24: ALB | C24: 2017 | D24: ECA | E24: 38 | F24: 91 | G24: 1.81 | H24: 8 | I24: 35 | J24: 41 | M24: 37 | N24: 37 | O24: 42 | P24: 47 | S24: 41 | T24: 33 | V24: 39 | W24: 30
A25: Albania | B25: ALB | C25: 2018 | D25: ECA | E25: 36 | F25: 99 | G25: 1.65 | H25: 8 | I25: 33 | J25: 39 | M25: 37 | N25: 37 | O25: 42 | P25: 35 | S25: 41 | T25: 29 | V25: 39 | W25: 30
A26: Albania | B26: ALB | C26: 2019 | D26: ECA | E26: 35 | F26: 106 | G26: 2.507669 | H26: 8 | I26: 30.88742 | J26: 39.11258 | M26: 37 | N26: 37 | O26: 42 | P26: 35 | S26: 41 | T26: 20 | V26: 37 | W26: 28
A27: Albania | B27: ALB | C27: 2020 | D27: ECA | E27: 36 | F27: 104 | G27: 0.915488 | H27: 8 | I27: 34.4986 | J27: 37.5014 | M27: 37 | N27: 37 | O27: 42 | P27: 35 | S27: 41 | T27: 32 | V27: 37 | W27: 30
A28: Albania | B28: ALB | C28: 2021 | D28: ECA | E28: 35 | F28: 110 | G28: 1.326029 | H28: 8 | I28: 32.81868 | J28: 37.18132 | M28: 40.82453 | N28: 37.26319 | O28: 41.52041 | P28: 34.50329 | S28: 39.03732 | T28: 24.63613 | V28: 32.22817 | W28: 30.19112
A29: Albania | B29: ALB | C29: 2022 | D29: ECA | E29: 36 | F29: 101 | G29: 1.316355 | H29: 8 | I29: 33.84118 | J29: 38.15882 | M29: 41 | N29: 37 | O29: 42 | P29: 35 | S29: 32 | T29: 27 | V29: 42 | W29: 29
A30: Albania | B30: ALB | C30: 2023 | D30: ECA | E30: 37 | F30: 98 | G30: 1.560074 | H30: 7 | I30: 34.44148 | J30: 39.55852 | M30: 44.81405 | N30: 37.26319 | O30: 44.48782 | P30: 34.50329 | S30: 32.41864 | T30: 36.21062 | W30: 29.29284
A31: Albania | B31: ALB | C31: 2024 | D31: ECA | E31: 42 | F31: 80 | G31: 3.030323 | H31: 8 | I31: 37.03027 | J31: 46.96973 | M31: 47.12976 | N31: 34.52117 | O31: 44.28328 | P31: 32.26798 | S31: 39.67784 | T31: 34.73275 | V31: 71.04935 | W31: 29.72035
A32: Albania | B32: ALB | C32: 2025 | D32: =VLOOKUP(B32,'CPI Timeseries 2012 - 2025'!B:C,2,0) -> ECA | E32: 39 | F32: 91 | G32: 2.411099 | H32: 7 | I32: 35.0458 | J32: 42.9542 | M32: 55.7342 | N32: 34.4944 | O32: 44.27766 | P32: 32.21466 | S32: 41.83633 | T32: 32 | W32: 31.43714
A33: Algeria | B33: DZA | C33: 2012 | D33: MENA | E33: 34 | F33: 105 | G33: 3.3 | H33: 6 | I33: 29 | J33: 40 | K33: 40 | M33: 36 | N33: 38 | P33: 42 | S33: 31 | V33: 20
A34: Algeria | B34: DZA | C34: 2013 | D34: MENA | E34: 36 | F34: 94 | G34: 2.8 | H34: 6 | I34: 31 | J34: 41 | K34: 42 | M34: 36 | N34: 38 | P34: 42 | S34: 31 | V34: 25
A35: Algeria | B35: DZA | C35: 2014 | D35: MENA | E35: 36 | F35: 100 | G35: 2.0599999 | H35: 5 | I35: 33 | J35: 39 | M35: 36 | N35: 38 | P35: 42 | S35: 31 | V35: 31
A36: Algeria | B36: DZA | C36: 2015 | D36: MENA | E36: 36 | F36: 88 | G36: 1.85 | H36: 5 | I36: 33 | J36: 39 | M36: 36 | N36: 38 | P36: 42 | S36: 31 | V36: 34
A37: Algeria | B37: DZA | C37: 2016 | D37: MENA | E37: 34 | F37: 108 | G37: 2.94 | H37: 6 | I37: 29 | J37: 39 | M37: 36 | N37: 37 | P37: 22 | S37: 32 | T37: 44 | V37: 33
A38: Algeria | B38: DZA | C38: 2017 | D38: MENA | E38: 33 | F38: 112 | G38: 2.32 | H38: 6 | I38: 29 | J38: 37 | M38: 37 | N38: 37 | P38: 22 | S38: 32 | T38: 37 | V38: 34
A39: Algeria | B39: DZA | C39: 2018 | D39: MENA | E39: 35 | F39: 105 | G39: 1.21 | H39: 6 | I39: 33 | J39: 37 | M39: 37 | N39: 37 | P39: 35 | S39: 32 | T39: 32 | V39: 39
A40: Algeria | B40: DZA | C40: 2019 | D40: MENA | E40: 35 | F40: 106 | G40: 2.590262 | H40: 7 | I40: 30.75197 | J40: 39.24803 | M40: 37 | N40: 37 | P40: 35 | S40: 32 | T40: 23 | V40: 46 | W40: 36
A41: Algeria | B41: DZA | C41: 2020 | D41: MENA | E41: 36 | F41: 104 | G41: 1.481484 | H41: 7 | I41: 33.57037 | J41: 38.42963 | M41: 37 | N41: 37 | P41: 35 | S41: 32 | T41: 28 | V41: 46 | W41: 37
...
